Workbook

Sheet in
A1: QuizName | B1: QuizClass | C1: FirstName | D1: LastName | E1: ZipGradeID | F1: ExternalID | G1: EarnedPts | H1: PossiblePts | I1: PercentCorrect | J1: QuizCreated | K1: DataExported | L1: KeyVersion | M1: P1 | N1: P2 | O1: P3 | P1: P4 | Q1: P5 | R1: P6 | S1: P7 | T1: P8 | U1: P9 | V1: P10 | W1: P11 | X1: P12 | Y1: P13 | Z1: P14 | AA1: P15 | AB1: P16 | AC1: P17 | AD1: P18 | AE1: P19 | AF1: P20 | AG1: P21 | AH1: P22 | AI1: P23 | AJ1: P24 | AK1: P25 | AL1: P26 | AM1: P27 | AN1: P28 | AO1: P29 | AP1: P30 | AQ1: P31 | AR1: P32 | AS1: P33 | AT1: P34 | AU1: P35 | AV1: P36 | AW1: P37 | AX1: P38 | AY1: P39 | AZ1: P40 | BA1: P41 | BB1: P42 | BC1: P43 | BD1: P44 | BE1: P45 | BF1: P46 | BG1: P47 | BH1: P48 | BI1: P49 | BJ1: P50 | BK1: P51 | BL1: P52 | BM1: P53 | BN1: P54 | BO1: P55 | BP1: P56 | BQ1: P57 | BR1: P58 | BS1: P59 | BT1: P60 | BU1: P61 | BV1: P62 | BW1: P63 | BX1: P64 | BY1: P65 | BZ1: P66 | CA1: P67 | CB1: P68 | CC1: P69 | CD1: P70 | CE1: P71 | CF1: P72 | CG1: P73 | CH1: P74 | CI1: P75 | CJ1: P76 | CK1: P77 | CL1: P78 | CM1: P79 | CN1: P80 | CO1: P81 | CP1: P82 | CQ1: P83 | CR1: P84 | CS1: P85 | CT1: P86 | CU1: P87 | CV1: P88 | CW1: P89 | CX1: P90 | CY1: P91 | CZ1: P93 | DA1: P94 | DB1: P95 | DC1: P96 | DD1: P97 | DE1: P98 | DF1: P99 | DG1: P100 | DH1: P104 | DI1: P110 | DJ1: P111 | DK1: P112 | DL1: P102 | DM1: P114 | DN1: P115 | DO1: P116 | DP1: P118 | DQ1: P119 | DR1: P101 | DS1: P103 | DT1: P105 | DU1: P106 | DV1: P107 | DW1: P108 | DX1: P109 | DY1: P120 | DZ1: P92 | EA1: P113 | EB1: P117 | EC1: R1 | ED1: R2 | EE1: R3 | EF1: R4 | EG1: R5 | EH1: R6 | EI1: R7 | EJ1: R8 | EK1: R9 | EL1: R10 | EM1: R11 | EN1: R12 | EO1: R13 | EP1: R14 | EQ1: R15 | ER1: R16 | ES1: R17 | ET1: R18 | EU1: R19 | EV1: R20 | EW1: R21 | EX1: R22 | EY1: R23 | EZ1: R24 | FA1: R25 | FB1: R26 | FC1: R27 | FD1: R28 | FE1: R29 | FF1: R30 | FG1: R31 | FH1: R32 | FI1: R33 | FJ1: R34 | FK1: R35 | FL1: R36 | FM1: R37 | FN1: R38 | FO1: R39 | FP1: R40 | FQ1: R41 | FR1: R42 | FS1: R43 | FT1: R44 | FU1: R45 | FV1: R46 | FW1: R47 | FX1: R48 | FY1: R49 | FZ1: R50 | GA1: R51 | GB1: R52 | GC1: R53 | GD1: R54 | GE1: R55 | GF1: R56 | GG1: R57 | GH1: R58 | GI1: R59 | GJ1: R60 | GK1: R61 | GL1: R62 | GM1: R63 | GN1: R64 | GO1: R65 | GP1: R66 | GQ1: R67 | GR1: R68 | GS1: R69 | GT1: R70 | GU1: R71 | GV1: R72 | GW1: R73 | GX1: R74 | GY1: R75 | GZ1: R76 | HA1: R77 | HB1: R78 | HC1: R79 | HD1: R80 | HE1: R81 | HF1: R82 | HG1: R83 | HH1: R84 | HI1: R85 | HJ1: R86 | HK1: R87 | HL1: R88 | HM1: R89 | HN1: R90 | HO1: R91 | HP1: R93 | HQ1: R94 | HR1: R95 | HS1: R96 | HT1: R97 | HU1: R98 | HV1: R99 | HW1: R100 | HX1: R104 | HY1: R110 | HZ1: R111 | IA1: R112 | IB1: R102 | IC1: R114 | ID1: R115 | IE1: R116 | IF1: R118 | IG1: R119 | IH1: R101 | II1: R103 | IJ1: R105 | IK1: R106 | IL1: R107 | IM1: R108 | IN1: R109 | IO1: R120 | IP1: R92 | IQ1: R113 | IR1: R117
A2: cerro tofeme monteria 1sesion [4053] | D2: AGRESOT SUAREZ DIEGO ALEJANDRO | E2: 5702 | G2: 92.0 | H2: 120.0 | I2: 76.7 | J2: mar. 14 2026 09:28 a.Â m. | K2: mar. 14 2026 09:34 a.Â m. | M2: 1 | N2: 1 | O2: 1 | P2: 1 | Q2: 1 | R2: 1 | S2: 0 | T2: 1 | U2: 0 | V2: 1 | W2: 1 | X2: 0 | Y2: 1 | Z2: 1 | AA2: 1 | AB2: 0 | AC2: 0 | AD2: 0 | AE2: 1 | AF2: 1 | AG2: 1 | AH2: 0 | AI2: 1 | AJ2: 0 | AK2: 1 | AL2: 1 | AM2: 1 | AN2: 0 | AO2: 1 | AP2: 1 | AQ2: 1 | AR2: 1 | AS2: 1 | AT2: 1 | AU2: 1 | AV2: 1 | AW2: 1 | AX2: 0 | AY2: 1 | AZ2: 1 | BA2: 1 | BB2: 1 | BC2: 1 | BD2: 0 | BE2: 1 | BF2: 0 | BG2: 0 | BH2: 1 | BI2: 1 | BJ2: 1 | BK2: 1 | BL2: 1 | BM2: 1 | BN2: 0 | BO2: 1 | BP2: 0 | BQ2: 0 | BR2: 1 | BS2: 1 | BT2: 1 | BU2: 0 | BV2: 0 | BW2: 1 | BX2: 1 | BY2: 1 | BZ2: 1 | CA2: 1 | CB2: 1 | CC2: 1 | CD2: 0 | CE2: 0 | CF2: 1 | CG2: 0 | CH2: 1 | CI2: 1 | CJ2: 1 | CK2: 1 | CL2: 1 | CM2: 1 | CN2: 1 | CO2: 0 | CP2: 1 | CQ2: 1 | CR2: 1 | CS2: 1 | CT2: 1 | CU2: 1 | CV2: 1 | CW2: 1 | CX2: 0 | CY2: 1 | CZ2: 1 | DA2: 1 | DB2: 1 | DC2: 1 | DD2: 1 | DE2: 1 | DF2: 1 | DG2: 1 | DH2: 1 | DI2: 1 | DJ2: 1 | DK2: 1 | DL2: 1 | DM2: 1 | DN2: 0 | DO2: 1 | DP2: 1 | DQ2: 1 | DR2: 0 | DS2: 0 | DT2: 0 | DU2: 0 | DV2: 1 | DW2: 1 | DX2: 1 | DY2: 1 | DZ2: 1 | EA2: 1 | EB2: 1 | EC2: C | ED2: B | EE2: B | EF2: B | EG2: C | EH2: B | EI2: A | EJ2: C | EK2: A | EL2: C | EM2: C | EN2: D | EO2: D | EP2: A | EQ2: B | ER2: D | ES2: A | ET2: B | EU2: D | EV2: D | EW2: B | EX2: D | EY2: D | EZ2: B | FA2: C | FB2: A | FC2: B | FD2: B | FE2: C | FF2: C | FG2: C | FH2: D | FI2: C | FJ2: D | FK2: A | FL2: D | FM2: A | FN2: C | FO2: C | FP2: C | FQ2: D | FR2: D | FS2: D | FT2: C | FU2: D | FV2: A | FW2: B | FX2: B | FY2: D | FZ2: C | GA2: B | GB2: C | GC2: D | GD2: C | GE2: C | GF2: A | GG2: A | GH2: A | GI2: A | GJ2: D | GK2: C | GL2: A | GM2: B | GN2: C | GO2: D | GP2: C | GQ2: B | GR2: A | GS2: A | GT2: A | GU2: C | GV2: A | GW2: D | GX2: B | GY2: B | GZ2: C | HA2: A | HB2: D | HC2: D | HD2: A | HE2: D | HF2: C | HG2: C | HH2: B | HI2: B | HJ2: C | HK2: B | HL2: B | HM2: D | HN2: B | HO2: B | HP2: B | HQ2: C | HR2: A | HS2: C | HT2: D | HU2: B | HV2: A | HW2: A | HX2: B | HY2: C | HZ2: B | IA2: C | IB2: B | IC2: B | ID2: C | IE2: A | IF2: B | IG2: C | IH2: C | II2: D | IJ2: B | IK2: C | IL2: B | IM2: C | IN2: B | IO2: C | IP2: C | IQ2: D | IR2: C
A3: cerro tofeme monteria 1sesion [4053] | D3: BRAVO FLOREZ MIGUEL ANDRES | E3: 5704 | G3: 48.0 | H3: 120.0 | I3: 40.0 | J3: mar. 14 2026 09:28 a.Â m. | K3: mar. 14 2026 09:34 a.Â m. | M3: 1 | N3: 1 | O3: 1 | P3: 0 | Q3: 0 | R3: 1 | S3: 0 | T3: 0 | U3: 1 | V3: 0 | W3: 0 | X3: 1 | Y3: 1 | Z3: 0 | AA3: 0 | AB3: 1 | AC3: 1 | AD3: 0 | AE3: 1 | AF3: 1 | AG3: 1 | AH3: 1 | AI3: 0 | AJ3: 0 | AK3: 1 | AL3: 0 | AM3: 0 | AN3: 1 | AO3: 1 | AP3: 0 | AQ3: 1 | AR3: 1 | AS3: 0 | AT3: 0 | AU3: 1 | AV3: 1 | AW3: 1 | AX3: 0 | AY3: 0 | AZ3: 1 | BA3: 1 | BB3: 0 | BC3: 0 | BD3: 1 | BE3: 0 | BF3: 0 | BG3: 0 | BH3: 0 | BI3: 0 | BJ3: 0 | BK3: 0 | BL3: 0 | BM3: 1 | BN3: 1 | BO3: 0 | BP3: 1 | BQ3: 0 | BR3: 1 | BS3: 1 | BT3: 0 | BU3: 0 | BV3: 1 | BW3: 1 | BX3: 0 | BY3: 0 | BZ3: 0 | CA3: 0 | CB3: 0 | CC3: 1 | CD3: 0 | CE3: 0 | CF3: 0 | CG3: 0 | CH3: 0 | CI3: 0 | CJ3: 0 | CK3: 1 | CL3: 1 | CM3: 0 | CN3: 1 | CO3: 1 | CP3: 0 | CQ3: 0 | CR3: 0 | CS3: 0 | CT3: 0 | CU3: 0 | CV3: 0 | CW3: 1 | CX3: 1 | CY3: 0 | CZ3: 1 | DA3: 0 | DB3: 0 | DC3: 1 | DD3: 0 | DE3: 0 | DF3: 0 | DG3: 0 | DH3: 1 | DI3: 0 | DJ3: 0 | DK3: 0 | DL3: 1 | DM3: 1 | DN3: 0 | DO3: 1 | DP3: 1 | DQ3: 0 | DR3: 0 | DS3: 1 | DT3: 0 | DU3: 0 | DV3: 0 | DW3: 0 | DX3: 0 | DY3: 0 | DZ3: 1 | EA3: 1 | EB3: 0 | EC3: C | ED3: B | EE3: B | EF3: A | EG3: D | EH3: B | EI3: A | EJ3: B | EK3: B | EL3: B | EM3: B | EN3: C | EO3: D | EP3: C | EQ3: C | ER3: C | ES3: D | ET3: D | EU3: D | EV3: D | EW3: B | EX3: C | EY3: C | EZ3: D | FA3: C | FB3: D | FC3: D | FD3: C | FE3: C | FF3: B | FG3: C | FH3: D | FI3: D | FJ3: B | FK3: A | FL3: D | FM3: A | FN3: A | FO3: A | FP3: C | FQ3: D | FR3: A | FS3: A | FT3: B | FU3: B | FV3: A | FW3: B | FX3: C | FY3: B | FZ3: A | GA3: D | GB3: B | GC3: D | GD3: B | GE3: B | GF3: B | GG3: C | GH3: A | GI3: A | GJ3: A | GK3: A | GL3: D | GM3: B | GN3: D | GO3: A | GP3: D | GQ3: C | GR3: B | GS3: A | GT3: B | GU3: C | GV3: C | GW3: B | GX3: A | GY3: D | GZ3: D | HA3: A | HB3: D | HC3: B | HD3: A | HE3: A | HF3: A | HG3: A | HH3: C | HI3: D | HJ3: A | HK3: D | HL3: A | HM3: D | HN3: A | HO3: A | HP3: B | HQ3: B | HR3: D | HS3: C | HT3: B | HU3: A | HV3: C | HW3: B | HX3: B | HY3: D | HZ3: D | IA3: D | IB3: B | IC3: B | ID3: B | IE3: A | IF3: B | IG3: B | IH3: B | II3: C | IJ3: D | IK3: D | IL3: C | IM3: B | IN3: A | IO3: A | IP3: C | IQ3: D | IR3: D
A4: cerro tofeme monteria 1sesion [4053] | D4: CALDERA CALVO MARIA ALEJANDRA | E4: 5705 | G4: 52.0 | H4: 120.0 | I4: 43.3 | J4: mar. 14 2026 09:28 a.Â m. | K4: mar. 14 2026 09:34 a.Â m. | M4: 1 | N4: 1 | O4: 1 | P4: 0 | Q4: 1 | R4: 0 | S4: 0 | T4: 0 | U4: 1 | V4: 0 | W4: 0 | X4: 0 | Y4: 1 | Z4: 0 | AA4: 1 | AB4: 0 | AC4: 0 | AD4: 0 | AE4: 1 | AF4: 1 | AG4: 0 | AH4: 1 | AI4: 0 | AJ4: 0 | AK4: 0 | AL4: 0 | AM4: 0 | AN4: 0 | AO4: 1 | AP4: 1 | AQ4: 1 | AR4: 0 | AS4: 1 | AT4: 0 | AU4: 1 | AV4: 1 | AW4: 0 | AX4: 0 | AY4: 0 | AZ4: 1 | BA4: 0 | BB4: 1 | BC4: 0 | BD4: 0 | BE4: 1 | BF4: 0 | BG4: 0 | BH4: 1 | BI4: 1 | BJ4: 0 | BK4: 1 | BL4: 0 | BM4: 0 | BN4: 1 | BO4: 1 | BP4: 0 | BQ4: 0 | BR4: 1 | BS4: 1 | BT4: 0 | BU4: 0 | BV4: 0 | BW4: 1 | BX4: 0 | BY4: 1 | BZ4: 1 | CA4: 0 | CB4: 0 | CC4: 1 | CD4: 0 | CE4: 0 | CF4: 0 | CG4: 0 | CH4: 1 | CI4: 0 | CJ4: 0 | CK4: 1 | CL4: 0 | CM4: 0 | CN4: 0 | CO4: 0 | CP4: 0 | CQ4: 1 | CR4: 1 | CS4: 1 | CT4: 1 | CU4: 0 | CV4: 0 | CW4: 0 | CX4: 0 | CY4: 1 | CZ4: 1 | DA4: 0 | DB4: 1 | DC4: 0 | DD4: 0 | DE4: 0 | DF4: 1 | DG4: 0 | DH4: 1 | DI4: 0 | DJ4: 0 | DK4: 0 | DL4: 1 | DM4: 0 | DN4: 1 | DO4: 1 | DP4: 1 | DQ4: 1 | DR4: 1 | DS4: 0 | DT4: 1 | DU4: 0 | DV4: 1 | DW4: 0 | DX4: 0 | DY4: 1 | DZ4: 0 | EA4: 1 | EB4: 1 | EC4: C | ED4: B | EE4: B | EF4: A | EG4: C | EH4: A | EI4: A | EJ4: D | EK4: B | EL4: B | EM4: B | EN4: D | EO4: D | EP4: C | EQ4: B | ER4: A | ES4: A | ET4: B | EU4: D | EV4: D | EW4: A | EX4: C | EY4: B | EZ4: B | FA4: A | FB4: D | FC4: A | FD4: B | FE4: C | FF4: C | FG4: C | FH4: A | FI4: C | FJ4: B | FK4: A | FL4: D | FM4: C | FN4: B | FO4: B | FP4: C | FQ4: A | FR4: D | FS4: C | FT4: C | FU4: D | FV4: A | FW4: A | FX4: B | FY4: D | FZ4: A | GA4: B | GB4: D | GC4: B | GD4: B | GE4: C | GF4: A | GG4: A | GH4: A | GI4: A | GJ4: A | GK4: C | GL4: B | GM4: B | GN4: A | GO4: D | GP4: C | GQ4: D | GR4: C | GS4: A | GT4: A | GU4: A | GV4: B | GW4: D | GX4: B | GY4: A | GZ4: A | HA4: A | HB4: A | HC4: B | HD4: C | HE4: B | HF4: B | HG4: C | HH4: B | HI4: B | HJ4: C | HK4: D | HL4: D | HM4: B | HN4: D | HO4: B | HP4: B | HQ4: A | HR4: A | HS4: A | HT4: C | HU4: C | HV4: A | HW4: D | HX4: B | HY4: A | HZ4: A | IA4: A | IB4: B | IC4: A | ID4: A | IE4: A | IF4: B | IG4: C | IH4: A | II4: B | IJ4: A | IK4: A | IL4: B | IM4: A | IN4: D | IO4: C | IP4: B | IQ4: D | IR4: C
A5: cerro tofeme monteria 1sesion [4053] | D5: CARVAJAL MIRANDA YOELIS MARIA | E5: 5706 | G5: 45.0 | H5: 120.0 | I5: 37.5 | J5: mar. 14 2026 09:28 a.Â m. | K5: mar. 14 2026 09:34 a.Â m. | M5: 1 | N5: 1 | O5: 0 | P5: 0 | Q5: 0 | R5: 1 | S5: 0 | T5: 0 | U5: 0 | V5: 0 | W5: 1 | X5: 0 | Y5: 0 | Z5: 0 | AA5: 0 | AB5: 0 | AC5: 0 | AD5: 0 | AE5: 0 | AF5: 0 | AG5: 1 | AH5: 1 | AI5: 0 | AJ5: 0 | AK5: 0 | AL5: 0 | AM5: 0 | AN5: 0 | AO5: 0 | AP5: 1 | AQ5: 0 | AR5: 0 | AS5: 0 | AT5: 1 | AU5: 1 | AV5: 1 | AW5: 1 | AX5: 0 | AY5: 1 | AZ5: 0 | BA5: 0 | BB5: 1 | BC5: 0 | BD5: 0 | BE5: 1 | BF5: 0 | BG5: 0 | BH5: 1 | BI5: 1 | BJ5: 1 | BK5: 1 | BL5: 0 | BM5: 0 | BN5: 0 | BO5: 1 | BP5: 1 | BQ5: 0 | BR5: 0 | BS5: 0 | BT5: 0 | BU5: 0 | BV5: 0 | BW5: 0 | BX5: 1 | BY5: 0 | BZ5: 1 | CA5: 0 | CB5: 1 | CC5: 1 | CD5: 0 | CE5: 1 | CF5: 0 | CG5: 1 | CH5: 1 | CI5: 0 | CJ5: 0 | CK5: 1 | CL5: 0 | CM5: 0 | CN5: 0 | CO5: 0 | CP5: 0 | CQ5: 0 | CR5: 0 | CS5: 1 | CT5: 1 | CU5: 0 | CV5: 0 | CW5: 0 | CX5: 0 | CY5: 1 | CZ5: 1 | DA5: 0 | DB5: 0 | DC5: 0 | DD5: 0 | DE5: 0 | DF5: 0 | DG5: 0 | DH5: 1 | DI5: 1 | DJ5: 1 | DK5: 1 | DL5: 1 | DM5: 1 | DN5: 0 | DO5: 0 | DP5: 1 | DQ5: 0 | DR5: 0 | DS5: 1 | DT5: 0 | DU5: 0 | DV5: 1 | DW5: 0 | DX5: 1 | DY5: 1 | DZ5: 0 | EA5: 1 | EB5: 1 | EC5: C | ED5: B | EE5: D | EF5: A | EG5: B | EH5: B | EI5: C | EJ5: B | EK5: C | EL5: B | EM5: C | EN5: D | EO5: A | EP5: C | EQ5: A | ER5: A | ES5: B | ET5: A | EU5: C | EV5: A | EW5: B | EX5: C | EY5: B | EZ5: D | FA5: B | FB5: B | FC5: C | FD5: A | FE5: B | FF5: C | FG5: B | FH5: C | FI5: B | FJ5: D | FK5: A | FL5: D | FM5: A | FN5: C | FO5: C | FP5: D | FQ5: A | FR5: D | FS5: B | FT5: C | FU5: D | FV5: B | FW5: B | FX5: B | FY5: D | FZ5: C | GA5: B | GB5: D | GC5: A | GD5: C | GE5: C | GF5: B | GG5: A | GH5: D | GI5: C | GJ5: A | GK5: C | GL5: B | GM5: C | GN5: C | GO5: B | GP5: C | GQ5: C | GR5: A | GS5: A | GT5: A | GU5: D | GV5: B | GW5: C | GX5: B | GY5: C | GZ5: B | HA5: A | HB5: C | HC5: B | HD5: C | HE5: B | HF5: B | HG5: A | HH5: C | HI5: B | HJ5: C | HK5: A | HL5: C | HM5: B | HN5: C | HO5: B | HP5: B | HQ5: D | HR5: C | HS5: B | HT5: C | HU5: A | HV5: C | HW5: B | HX5: B | HY5: C | HZ5: B | IA5: C | IB5: B | IC5: B | ID5: D | IE5: B | IF5: B | IG5: A | IH5: C | II5: C | IJ5: D | IK5: C | IL5: B | IM5: B | IN5: B | IO5: C | IP5: D | IQ5: D | IR5: C
A6: cerro tofeme monteria 1sesion [4053] | D6: DIAZ DONADO ROSA ANDREA | E6: 5707 | G6: 51.0 | H6: 120.0 | I6: 42.5 | J6: mar. 14 2026 09:28 a.Â m. | K6: mar. 14 2026 09:34 a.Â m. | M6: 1 | N6: 1 | O6: 1 | P6: 0 | Q6: 0 | R6: 1 | S6: 0 | T6: 0 | U6: 1 | V6: 1 | W6: 1 | X6: 1 | Y6: 1 | Z6: 0 | AA6: 0 | AB6: 1 | AC6: 0 | AD6: 0 | AE6: 1 | AF6: 0 | AG6: 0 | AH6: 0 | AI6: 0 | AJ6: 0 | AK6: 1 | AL6: 0 | AM6: 0 | AN6: 1 | AO6: 1 | AP6: 1 | AQ6: 1 | AR6: 1 | AS6: 1 | AT6: 1 | AU6: 1 | AV6: 1 | AW6: 0 | AX6: 0 | AY6: 1 | AZ6: 1 | BA6: 1 | BB6: 0 | BC6: 1 | BD6: 0 | BE6: 1 | BF6: 0 | BG6: 0 | BH6: 1 | BI6: 1 | BJ6: 1 | BK6: 0 | BL6: 0 | BM6: 1 | BN6: 0 | BO6: 1 | BP6: 0 | BQ6: 0 | BR6: 1 | BS6: 0 | BT6: 0 | BU6: 1 | BV6: 0 | BW6: 0 | BX6: 1 | BY6: 0 | BZ6: 1 | CA6: 0 | CB6: 0 | CC6: 0 | CD6: 1 | CE6: 0 | CF6: 0 | CG6: 0 | CH6: 1 | CI6: 0 | CJ6: 1 | CK6: 0 | CL6: 0 | CM6: 0 | CN6: 0 | CO6: 0 | CP6: 1 | CQ6: 0 | CR6: 0 | CS6: 1 | CT6: 0 | CU6: 0 | CV6: 1 | CW6: 0 | CX6: 0 | CY6: 1 | CZ6: 0 | DA6: 0 | DB6: 0 | DC6: 0 | DD6: 0 | DE6: 0 | DF6: 1 | DG6: 1 | DH6: 0 | DI6: 1 | DJ6: 0 | DK6: 0 | DL6: 1 | DM6: 0 | DN6: 0 | DO6: 0 | DP6: 1 | DQ6: 1 | DR6: 0 | DS6: 1 | DT6: 1 | DU6: 0 | DV6: 0 | DW6: 0 | DX6: 1 | DY6: 0 | DZ6: 0 | EA6: 0 | EB6: 0 | EC6: C | ED6: B | EE6: B | EF6: D | EG6: B | EH6: B | EI6: A | EJ6: B | EK6: B | EL6: C | EM6: C | EN6: C | EO6: D | EP6: C | EQ6: C | ER6: C | ES6: A | ET6: D | EU6: D | EV6: A | EW6: D | EX6: B | EY6: B | EZ6: D | FA6: C | FB6: D | FC6: C | FD6: C | FE6: C | FF6: C | FG6: C | FH6: D | FI6: C | FJ6: D | FK6: A | FL6: D | FM6: D | FN6: C | FO6: C | FP6: C | FQ6: D | FR6: A | FS6: D | FT6: D | FU6: D | FV6: A | FW6: A | FX6: B | FY6: D | FZ6: C | GA6: C | GB6: D | GC6: D | GD6: C | GE6: C | GF6: D | GG6: A | GH6: A | GI6: C | GJ6: B | GK6: D | GL6: C | GM6: C | GN6: C | GO6: B | GP6: C | GQ6: C | GR6: C | GS6: B | GT6: C | GU6: C | GV6: B | GW6: B | GX6: B | GY6: C | GZ6: C | HA6: D | HB6: B | HC6: A | HD6: C | HE6: C | HF6: C | HG6: D | HH6: D | HI6: B | HJ6: B | HK6: C | HL6: B | HM6: C | HN6: B | HO6: B | HP6: C | HQ6: D | HR6: B | HS6: A | HT6: B | HU6: C | HV6: A | HW6: A | HX6: C | HY6: C | HZ6: A | IA6: D | IB6: B | IC6: D | ID6: B | IE6: C | IF6: B | IG6: C | IH6: D | II6: C | IJ6: A | IK6: A | IL6: C | IM6: B | IN6: B | IO6: B | IP6: B | IQ6: B | IR6: D
A7: cerro tofeme monteria 1sesion [4053] | D7: DIAZ MARTINEZ DINA MARCELA | E7: 5708 | G7: 48.0 | H7: 120.0 | I7: 40.0 | J7: mar. 14 2026 09:28 a.Â m. | K7: mar. 14 2026 09:34 a.Â m. | M7: 1 | N7: 1 | O7: 0 | P7: 0 | Q7: 0 | R7: 1 | S7: 0 | T7: 0 | U7: 1 | V7: 0 | W7: 0 | X7: 1 | Y7: 0 | Z7: 0 | AA7: 1 | AB7: 0 | AC7: 0 | AD7: 0 | AE7: 1 | AF7: 0 | AG7: 1 | AH7: 0 | AI7: 1 | AJ7: 0 | AK7: 0 | AL7: 0 | AM7: 0 | AN7: 1 | AO7: 1 | AP7: 1 | AQ7: 0 | AR7: 1 | AS7: 0 | AT7: 0 | AU7: 0 | AV7: 0 | AW7: 1 | AX7: 0 | AY7: 1 | AZ7: 1 | BA7: 0 | BB7: 0 | BC7: 0 | BD7: 1 | BE7: 1 | BF7: 0 | BG7: 0 | BH7: 1 | BI7: 1 | BJ7: 0 | BK7: 0 | BL7: 1 | BM7: 1 | BN7: 0 | BO7: 1 | BP7: 1 | BQ7: 0 | BR7: 0 | BS7: 0 | BT7: 0 | BU7: 0 | BV7: 0 | BW7: 0 | BX7: 0 | BY7: 1 | BZ7: 0 | CA7: 0 | CB7: 1 | CC7: 0 | CD7: 0 | CE7: 1 | CF7: 1 | CG7: 0 | CH7: 0 | CI7: 1 | CJ7: 1 | CK7: 1 | CL7: 1 | CM7: 0 | CN7: 0 | CO7: 1 | CP7: 0 | CQ7: 1 | CR7: 1 | CS7: 0 | CT7: 1 | CU7: 0 | CV7: 0 | CW7: 0 | CX7: 0 | CY7: 1 | CZ7: 1 | DA7: 0 | DB7: 1 | DC7: 0 | DD7: 0 | DE7: 0 | DF7: 1 | DG7: 0 | DH7: 0 | DI7: 1 | DJ7: 0 | DK7: 0 | DL7: 0 | DM7: 0 | DN7: 0 | DO7: 0 | DP7: 1 | DQ7: 1 | DR7: 0 | DS7: 0 | DT7: 1 | DU7: 0 | DV7: 1 | DW7: 0 | DX7: 1 | DY7: 0 | DZ7: 1 | EA7: 0 | EB7: 1 | EC7: C | ED7: B | EE7: C | EF7: A | EG7: A | EH7: B | EI7: C | EJ7: D | EK7: B | EL7: A | EM7: B | EN7: C | EO7: A | EP7: C | EQ7: B | ER7: A | ES7: A | ET7: D | EU7: D | EV7: A | EW7: B | EX7: B | EY7: D | EZ7: D | FA7: A | FB7: D | FC7: A | FD7: C | FE7: C | FF7: C | FG7: B | FH7: D | FI7: B | FJ7: B | FK7: C | FL7: C | FM7: A | FN7: B | FO7: C | FP7: C | FQ7: A | FR7: B | FS7: A | FT7: B | FU7: D | FV7: A | FW7: A | FX7: B | FY7: D | FZ7: B | GA7: A | GB7: C | GC7: D | GD7: C | GE7: C | GF7: B | GG7: D | GH7: D | GI7: B | GJ7: A | GK7: A | GL7: C | GM7: A | GN7: B | GO7: D | GP7: A | GQ7: C | GR7: A | GS7: C | GT7: B | GU7: D | GV7: A | GW7: D | GX7: A | GY7: B | GZ7: C | HA7: A | HB7: D | HC7: A | HD7: C | HE7: A | HF7: B | HG7: C | HH7: B | HI7: D | HJ7: C | HK7: A | HL7: C | HM7: B | HN7: D | HO7: B | HP7: B | HQ7: A | HR7: A | HS7: B | HT7: C | HU7: C | HV7: A | HW7: D | HX7: C | HY7: C | HZ7: A | IA7: B | IB7: C | IC7: D | ID7: B | IE7: D | IF7: B | IG7: C | IH7: C | II7: A | IJ7: A | IK7: C | IL7: B | IM7: B | IN7: B | IO7: A | IP7: C | IQ7: A | IR7: C
A8: cerro tofeme monteria 1sesion [4053] | D8: LAGARES PEREZ OVIER ANTONIO | E8: 5709 | G8: 56.0 | H8: 120.0 | I8: 46.7 | J8: mar. 14 2026 09:28 a.Â m. | K8: mar. 14 2026 09:34 a.Â m. | M8: 1 | N8: 1 | O8: 0 | P8: 1 | Q8: 0 | R8: 0 | S8: 0 | T8: 0 | U8: 1 | V8: 0 | W8: 1 | X8: 1 | Y8: 1 | Z8: 0 | AA8: 1 | AB8: 1 | AC8: 0 | AD8: 1 | AE8: 1 | AF8: 1 | AG8: 0 | AH8: 0 | AI8: 0 | AJ8: 1 | AK8: 0 | AL8: 0 | AM8: 0 | AN8: 1 | AO8: 1 | AP8: 1 | AQ8: 1 | AR8: 0 | AS8: 0 | AT8: 1 | AU8: 1 | AV8: 1 | AW8: 1 | AX8: 0 | AY8: 0 | AZ8: 1 | BA8: 1 | BB8: 1 | BC8: 0 | BD8: 0 | BE8: 0 | BF8: 0 | BG8: 0 | BH8: 1 | BI8: 1 | BJ8: 1 | BK8: 0 | BL8: 1 | BM8: 1 | BN8: 0 | BO8: 1 | BP8: 0 | BQ8: 0 | BR8: 0 | BS8: 1 | BT8: 0 | BU8: 1 | BV8: 0 | BW8: 0 | BX8: 1 | BY8: 0 | BZ8: 1 | CA8: 1 | CB8: 0 | CC8: 1 | CD8: 0 | CE8: 1 | CF8: 0 | CG8: 1 | CH8: 1 | CI8: 0 | CJ8: 0 | CK8: 1 | CL8: 0 | CM8: 1 | CN8: 1 | CO8: 1 | CP8: 1 | CQ8: 0 | CR8: 0 | CS8: 1 | CT8: 1 | CU8: 1 | CV8: 0 | CW8: 0 | CX8: 0 | CY8: 0 | CZ8: 1 | DA8: 0 | DB8: 0 | DC8: 0 | DD8: 1 | DE8: 1 | DF8: 0 | DG8: 1 | DH8: 0 | DI8: 1 | DJ8: 0 | DK8: 0 | DL8: 0 | DM8: 0 | DN8: 0 | DO8: 0 | DP8: 1 | DQ8: 0 | DR8: 0 | DS8: 0 | DT8: 0 | DU8: 0 | DV8: 1 | DW8: 0 | DX8: 1 | DY8: 0 | DZ8: 0 | EA8: 1 | EB8: 0 | EC8: C | ED8: B | EE8: C | EF8: B | EG8: A | EH8: A | EI8: C | EJ8: D | EK8: B | EL8: D | EM8: C | EN8: C | EO8: D | EP8: C | EQ8: B | ER8: C | ES8: A | ET8: C | EU8: D | EV8: D | EW8: C | EX8: D | EY8: B | EZ8: C | FA8: A | FB8: D | FC8: A | FD8: C | FE8: C | FF8: C | FG8: C | FH8: B | FI8: B | FJ8: D | FK8: A | FL8: D | FM8: A | FN8: B | FO8: B | FP8: C | FQ8: D | FR8: D | FS8: C | FT8: C | FU8: B | FV8: A | FW8: B | FX8: B | FY8: D | FZ8: C | GA8: A | GB8: C | GC8: D | GD8: C | GE8: C | GF8: A | GG8: C | GH8: D | GI8: A | GJ8: C | GK8: D | GL8: A | GM8: C | GN8: C | GO8: A | GP8: C | GQ8: B | GR8: B | GS8: A | GT8: A | GU8: D | GV8: B | GW8: C | GX8: B | GY8: C | GZ8: A | HA8: A | HB8: B | HC8: D | HD8: A | HE8: A | HF8: C | HG8: A | HH8: C | HI8: B | HJ8: C | HK8: B | HL8: A | HM8: C | HN8: D | HO8: A | HP8: B | HQ8: A | HR8: C | HS8: A | HT8: D | HU8: B | HV8: B | HW8: A | HX8: A | HY8: C | HZ8: A | IA8: B | IB8: C | IC8: C | ID8: C | IE8: B | IF8: B | IG8: A | IH8: B | II8: B | IJ8: C | IK8: A | IL8: B | IM8: B | IN8: B | IO8: B | IP8: D | IQ8: D | IR8: A
A9: cerro tofeme monteria 1sesion [4053] | D9: SANTANA RAMOS EUSEBIO | E9: 5711 | G9: 63.0 | H9: 120.0 | I9: 52.5 | J9: mar. 14 2026 09:28 a.Â m. | K9: mar. 14 2026 09:34 a.Â m. | M9: 1 | N9: 1 | O9: 1 | P9: 0 | Q9: 0 | R9: 1 | S9: 0 | T9: 1 | U9: 0 | V9: 1 | W9: 0 | X9: 0 | Y9: 1 | Z9: 0 | AA9: 0 | AB9: 1 | AC9: 0 | AD9: 0 | AE9: 1 | AF9: 1 | AG9: 1 | AH9: 0 | AI9: 0 | AJ9: 1 | AK9: 0 | AL9: 0 | AM9: 1 | AN9: 1 | AO9: 0 | AP9: 1 | AQ9: 0 | AR9: 0 | AS9: 1 | AT9: 1 | AU9: 1 | AV9: 1 | AW9: 0 | AX9: 0 | AY9: 0 | AZ9: 1 | BA9: 1 | BB9: 1 | BC9: 1 | BD9: 0 | BE9: 1 | BF9: 1 | BG9: 1 | BH9: 1 | BI9: 1 | BJ9: 0 | BK9: 1 | BL9: 0 | BM9: 1 | BN9: 0 | BO9: 1 | BP9: 0 | BQ9: 0 | BR9: 1 | BS9: 1 | BT9: 1 | BU9: 0 | BV9: 0 | BW9: 0 | BX9: 1 | BY9: 0 | BZ9: 0 | CA9: 0 | CB9: 1 | CC9: 1 | CD9: 0 | CE9: 0 | CF9: 1 | CG9: 0 | CH9: 1 | CI9: 0 | CJ9: 0 | CK9: 1 | CL9: 0 | CM9: 0 | CN9: 0 | CO9: 1 | CP9: 0 | CQ9: 0 | CR9: 1 | CS9: 1 | CT9: 1 | CU9: 0 | CV9: 1 | CW9: 1 | CX9: 0 | CY9: 1 | CZ9: 1 | DA9: 1 | DB9: 1 | DC9: 0 | DD9: 0 | DE9: 0 | DF9: 0 | DG9: 0 | DH9: 0 | DI9: 1 | DJ9: 1 | DK9: 0 | DL9: 1 | DM9: 1 | DN9: 1 | DO9: 0 | DP9: 1 | DQ9: 1 | DR9: 0 | DS9: 1 | DT9: 1 | DU9: 0 | DV9: 1 | DW9: 0 | DX9: 0 | DY9: 0 | DZ9: 1 | EA9: 1 | EB9: 1 | EC9: C | ED9: B | EE9: B | EF9: C | EG9: D | EH9: B | EI9: A | EJ9: C | EK9: A | EL9: C | EM9: A | EN9: D | EO9: D | EP9: D | EQ9: C | ER9: C | ES9: A | ET9: A | EU9: D | EV9: D | EW9: B | EX9: B | EY9: C | EZ9: C | FA9: D | FB9: D | FC9: B | FD9: C | FE9: D | FF9: C | FG9: B | FH9: A | FI9: C | FJ9: D | FK9: A | FL9: D | FM9: B | FN9: B | FO9: A | FP9: C | FQ9: D | FR9: D | FS9: D | FT9: D | FU9: D | FV9: C | FW9: D | FX9: B | FY9: D | FZ9: A | GA9: B | GB9: B | GC9: D | GD9: D | GE9: C | GF9: D | GG9: A | GH9: A | GI9: A | GJ9: D | GK9: A | GL9: A | GM9: D | GN9: C | GO9: C | GP9: D | GQ9: C | GR9: A | GS9: A | GT9: A | GU9: C | GV9: A | GW9: A | GX9: B | GY9: A | GZ9: D | HA9: A | HB9: B | HC9: B | HD9: B | HE9: A | HF9: A | HG9: A | HH9: B | HI9: B | HJ9: C | HK9: C | HL9: B | HM9: D | HN9: B | HO9: B | HP9: B | HQ9: C | HR9: A | HS9: A | HT9: A | HU9: C | HV9: B | HW9: B | HX9: A | HY9: C | HZ9: B | IA9: A | IB9: B | IC9: B | ID9: A | IE9: C | IF9: B | IG9: C | IH9: C | II9: C | IJ9: A | IK9: A | IL9: B | IM9: A | IN9: A | IO9: A | IP9: C | IQ9: D | IR9: C
A10: cerro tofeme monteria 1sesion [4053] | D10: TRIVIÑO AYALA JONATHAN | E10: 5712 | G10: 56.0 | H10: 120.0 | I10: 46.7 | J10: mar. 14 2026 09:28 a.Â m. | K10: mar. 14 2026 09:34 a.Â m. | M10: 1 | N10: 1 | O10: 0 | P10: 0 | Q10: 0 | R10: 1 | S10: 1 | T10: 0 | U10: 1 | V10: 0 | W10: 0 | X10: 0 | Y10: 1 | Z10: 0 | AA10: 1 | AB10: 0 | AC10: 1 | AD10: 0 | AE10: 1 | AF10: 1 | AG10: 1 | AH10: 1 | AI10: 1 | AJ10: 1 | AK10: 0 | AL10: 0 | AM10: 0 | AN10: 1 | AO10: 1 | AP10: 1 | AQ10: 1 | AR10: 1 | AS10: 0 | AT10: 1 | AU10: 1 | AV10: 1 | AW10: 1 | AX10: 0 | AY10: 1 | AZ10: 0 | BA10: 0 | BB10: 0 | BC10: 0 | BD10: 1 | BE10: 0 | BF10: 0 | BG10: 0 | BH10: 1 | BI10: 0 | BJ10: 0 | BK10: 1 | BL10: 1 | BM10: 1 | BN10: 0 | BO10: 0 | BP10: 1 | BQ10: 1 | BR10: 1 | BS10: 1 | BT10: 1 | BU10: 0 | BV10: 1 | BW10: 0 | BX10: 0 | BY10: 0 | BZ10: 0 | CA10: 0 | CB10: 0 | CC10: 1 | CD10: 0 | CE10: 1 | CF10: 0 | CG10: 0 | CH10: 0 | CI10: 0 | CJ10: 1 | CK10: 1 | CL10: 0 | CM10: 0 | CN10: 0 | CO10: 0 | CP10: 0 | CQ10: 0 | CR10: 0 | CS10: 0 | CT10: 1 | CU10: 0 | CV10: 0 | CW10: 1 | CX10: 0 | CY10: 1 | CZ10: 1 | DA10: 0 | DB10: 1 | DC10: 0 | DD10: 0 | DE10: 1 | DF10: 1 | DG10: 0 | DH10: 0 | DI10: 1 | DJ10: 0 | DK10: 1 | DL10: 1 | DM10: 0 | DN10: 1 | DO10: 0 | DP10: 1 | DQ10: 1 | DR10: 0 | DS10: 0 | DT10: 1 | DU10: 0 | DV10: 1 | DW10: 0 | DX10: 0 | DY10: 0 | DZ10: 1 | EA10: 0 | EB10: 1 | EC10: C | ED10: B | EE10: C | EF10: A | EG10: D | EH10: B | EI10: D | EJ10: D | EK10: B | EL10: B | EM10: B | EN10: D | EO10: D | EP10: C | EQ10: B | ER10: B | ES10: D | ET10: B | EU10: D | EV10: D | EW10: B | EX10: C | EY10: D | EZ10: C | FA10: A | FB10: D | FC10: D | FD10: C | FE10: C | FF10: C | FG10: C | FH10: D | FI10: B | FJ10: D | FK10: A | FL10: D | FM10: A | FN10: C | FO10: C | FP10: B | FQ10: A | FR10: C | FS10: C | FT10: B | FU10: C | FV10: A | FW10: A | FX10: B | FY10: A | FZ10: D | GA10: B | GB10: C | GC10: D | GD10: D | GE10: D | GF10: B | GG10: B | GH10: A | GI10: A | GJ10: D | GK10: A | GL10: D | GM10: C | GN10: D | GO10: C | GP10: D | GQ10: C | GR10: C | GS10: A | GT10: B | GU10: D | GV10: C | GW10: D | GX10: A | GY10: C | GZ10: C | HA10: A | HB10: B | HC10: B | HD10: C | HE10: C | HF10: A | HG10: D | HH10: A | HI10: C | HJ10: C | HK10: D | HL10: D | HM10: D | HN10: C | HO10: B | HP10: B | HQ10: A | HR10: A | HS10: A | HT10: C | HU10: B | HV10: A | HW10: B | HX10: C | HY10: C | HZ10: A | IA10: C | IB10: B | IC10: C | ID10: A | IE10: D | IF10: B | IG10: C | IH10: C | II10: B | IJ10: A | IK10: A | IL10: B | IM10: D | IN10: A | IO10: D | IP10: C | IQ10: A | IR10: C
A11: cerro tofeme monteria 1sesion [4053] | D11: VELASQUEZ GANOT MARIA JOSE | E11: 5713 | G11: 47.0 | H11: 120.0 | I11: 39.2 | J11: mar. 14 2026 09:28 a.Â m. | K11: mar. 14 2026 09:34 a.Â m. | M11: 1 | N11: 1 | O11: 0 | P11: 0 | Q11: 1 | R11: 1 | S11: 0 | T11: 1 | U11: 1 | V11: 0 | W11: 0 | X11: 1 | Y11: 0 | Z11: 0 | AA11: 0 | AB11: 0 | AC11: 0 | AD11: 1 | AE11: 1 | AF11: 0 | AG11: 0 | AH11: 0 | AI11: 0 | AJ11: 0 | AK11: 1 | AL11: 1 | AM11: 1 | AN11: 0 | AO11: 1 | AP11: 1 | AQ11: 1 | AR11: 0 | AS11: 0 | AT11: 0 | AU11: 1 | AV11: 1 | AW11: 0 | AX11: 0 | AY11: 0 | AZ11: 1 | BA11: 1 | BB11: 0 | BC11: 0 | BD11: 0 | BE11: 0 | BF11: 0 | BG11: 0 | BH11: 1 | BI11: 1 | BJ11: 1 | BK11: 1 | BL11: 0 | BM11: 1 | BN11: 1 | BO11: 0 | BP11: 1 | BQ11: 0 | BR11: 0 | BS11: 0 | BT11: 0 | BU11: 0 | BV11: 0 | BW11: 1 | BX11: 0 | BY11: 0 | BZ11: 1 | CA11: 0 | CB11: 0 | CC11: 0 | CD11: 0 | CE11: 0 | CF11: 0 | CG11: 0 | CH11: 1 | CI11: 1 | CJ11: 1 | CK11: 1 | CL11: 0 | CM11: 0 | CN11: 1 | CO11: 0 | CP11: 0 | CQ11: 0 | CR11: 0 | CS11: 0 | CT11: 1 | CU11: 0 | CV11: 0 | CW11: 1 | CX11: 0 | CY11: 1 | CZ11: 1 | DA11: 0 | DB11: 0 | DC11: 1 | DD11: 0 | DE11: 0 | DF11: 1 | DG11: 0 | DH11: 0 | DI11: 1 | DJ11: 0 | DK11: 0 | DL11: 1 | DM11: 1 | DN11: 0 | DO11: 0 | DP11: 1 | DQ11: 0 | DR11: 0 | DS11: 0 | DT11: 0 | DU11: 1 | DV11: 0 | DW11: 0 | DX11: 1 | DY11: 1 | DZ11: 1 | EA11: 0 | EB11: 0 | EC11: C | ED11: B | EE11: C | EF11: A | EG11: C | EH11: B | EI11: C | EJ11: C | EK11: B | EL11: B | EM11: B | EN11: C | EO11: C | EP11: C | EQ11: D | ER11: A | ES11: C | ET11: C | EU11: D | EV11: A | EW11: D | EX11: B | EY11: C | EZ11: B | FA11: C | FB11: A | FC11: B | FD11: A | FE11: C | FF11: C | FG11: C | FH11: C | FI11: D | FJ11: C | FK11: A | FL11: D | FM11: C | FN11: B | FO11: B | FP11: C | FQ11: D | FR11: C | FS11: C | FT11: C | FU11: C | FV11: B | FW11: B | FX11: B | FY11: D | FZ11: C | GA11: B | GB11: B | GC11: D | GD11: B | GE11: B | GF11: B | GG11: C | GH11: B | GI11: B | GJ11: A | GK11: C | GL11: C | GM11: B | GN11: B | GO11: B | GP11: C | GQ11: C | GR11: B | GS11: B | GT11: A | GU11: C | GV11: C | GW11: B | GX11: B | GY11: B | GZ11: C | HA11: A | HB11: B | HC11: B | HD11: A | HE11: B | HF11: A | HG11: B | HH11: C | HI11: D | HJ11: C | HK11: C | HL11: A | HM11: D | HN11: C | HO11: B | HP11: B | HQ11: B | HR11: C | HS11: C | HT11: B | HU11: C | HV11: A | HW11: B | HX11: C | HY11: C | HZ11: A | IA11: A | IB11: B | IC11: B | ID11: D | IE11: D | IF11: B | IG11: A | IH11: B | II11: B | IJ11: D | IK11: B | IL11: C | IM11: B | IN11: B | IO11: C | IP11: C | IQ11: C | IR11: B
A12: cerro tofeme monteria 1sesion [4053] | D12: ZARZA BARRAGAN JOHAN SEBASTIAN | E12: 5714 | G12: 39.0 | H12: 120.0 | I12: 32.5 | J12: mar. 14 2026 09:28 a.Â m. | K12: mar. 14 2026 09:34 a.Â m. | M12: 1 | N12: 1 | O12: 1 | P12: 0 | Q12: 0 | R12: 1 | S12: 0 | T12: 0 | U12: 1 | V12: 0 | W12: 1 | X12: 0 | Y12: 0 | Z12: 0 | AA12: 0 | AB12: 0 | AC12: 0 | AD12: 0 | AE12: 1 | AF12: 1 | AG12: 0 | AH12: 1 | AI12: 0 | AJ12: 0 | AK12: 0 | AL12: 0 | AM12: 0 | AN12: 0 | AO12: 1 | AP12: 0 | AQ12: 1 | AR12: 0 | AS12: 0 | AT12: 0 | AU12: 0 | AV12: 0 | AW12: 1 | AX12: 0 | AY12: 1 | AZ12: 1 | BA12: 1 | BB12: 0 | BC12: 0 | BD12: 0 | BE12: 1 | BF12: 0 | BG12: 0 | BH12: 1 | BI12: 0 | BJ12: 0 | BK12: 0 | BL12: 0 | BM12: 0 | BN12: 1 | BO12: 0 | BP12: 1 | BQ12: 1 | BR12: 1 | BS12: 0 | BT12: 0 | BU12: 0 | BV12: 0 | BW12: 0 | BX12: 1 | BY12: 0 | BZ12: 0 | CA12: 0 | CB12: 1 | CC12: 0 | CD12: 0 | CE12: 1 | CF12: 0 | CG12: 0 | CH12: 0 | CI12: 0 | CJ12: 0 | CK12: 1 | CL12: 1 | CM12: 0 | CN12: 0 | CO12: 0 | CP12: 0 | CQ12: 0 | CR12: 1 | CS12: 0 | CT12: 0 | CU12: 0 | CV12: 0 | CW12: 1 | CX12: 0 | CY12: 0 | CZ12: 1 | DA12: 1 | DB12: 0 | DC12: 0 | DD12: 1 | DE12: 0 | DF12: 0 | DG12: 0 | DH12: 0 | DI12: 1 | DJ12: 0 | DK12: 0 | DL12: 0 | DM12: 0 | DN12: 0 | DO12: 1 | DP12: 1 | DQ12: 1 | DR12: 0 | DS12: 0 | DT12: 1 | DU12: 0 | DV12: 0 | DW12: 0 | DX12: 0 | DY12: 0 | DZ12: 1 | EA12: 1 | EB12: 1 | EC12: C | ED12: B | EE12: B | EF12: A | EG12: B | EH12: B | EI12: A | EJ12: B | EK12: B | EL12: B | EM12: C | EN12: D | EO12: A | EP12: C | EQ12: D | ER12: D | ES12: A | ET12: D | EU12: D | EV12: D | EW12: D | EX12: C | EY12: B | EZ12: B | FA12: D | FB12: D | FC12: A | FD12: A | FE12: C | FF12: A | FG12: C | FH12: C | FI12: D | FJ12: C | FK12: B | FL12: C | FM12: A | FN12: C | FO12: C | FP12: C | FQ12: D | FR12: C | FS12: B | FT12: C | FU12: D | FV12: D | FW12: A | FX12: B | FY12: A | FZ12: D | GA12: A | GB12: A | GC12: A | GD12: B | GE12: B | GF12: B | GG12: B | GH12: A | GI12: C | GJ12: A | GK12: A | GL12: C | GM12: C | GN12: C | GO12: A | GP12: B | GQ12: D | GR12: A | GS12: B | GT12: A | GU12: D | GV12: C | GW12: D | GX12: C | GY12: D | GZ12: B | HA12: A | HB12: D | HC12: C | HD12: C | HE12: B | HF12: A | HG12: B | HH12: B | HI12: C | HJ12: B | HK12: C | HL12: A | HM12: D | HN12: D | HO12: C | HP12: B | HQ12: C | HR12: C | HS12: A | HT12: D | HU12: A | HV12: C | HW12: B | HX12: D | HY12: C | HZ12: A | IA12: D | IB12: A | IC12: A | ID12: C | IE12: A | IF12: B | IG12: C | IH12: C | II12: D | IJ12: A | IK12: C | IL12: C | IM12: A | IN12: A | IO12: A | IP12: C | IQ12: D | IR12: C
A13: cerro tofeme monteria 1sesion [4053] | D13: BENITEZ GALINDO SAMUEL DAVID | E13: 5801 | G13: 38.0 | H13: 120.0 | I13: 31.7 | J13: mar. 14 2026 09:30 a.Â m. | K13: mar. 14 2026 09:34 a.Â m. | M13: 1 | N13: 0 | O13: 1 | P13: 0 | Q13: 0 | R13: 0 | S13: 0 | T13: 1 | U13: 1 | V13: 0 | W13: 0 | X13: 1 | Y13: 1 | Z13: 0 | AA13: 0 | AB13: 0 | AC13: 0 | AD13: 0 | AE13: 0 | AF13: 0 | AG13: 0 | AH13: 1 | AI13: 0 | AJ13: 1 | AK13: 0 | AL13: 0 | AM13: 0 | AN13: 1 | AO13: 1 | AP13: 0 | AQ13: 0 | AR13: 0 | AS13: 0 | AT13: 0 | AU13: 1 | AV13: 1 | AW13: 0 | AX13: 1 | AY13: 0 | AZ13: 1 | BA13: 1 | BB13: 0 | BC13: 0 | BD13: 1 | BE13: 1 | BF13: 0 | BG13: 0 | BH13: 1 | BI13: 0 | BJ13: 0 | BK13: 1 | BL13: 0 | BM13: 0 | BN13: 1 | BO13: 0 | BP13: 0 | BQ13: 1 | BR13: 1 | BS13: 0 | BT13: 0 | BU13: 0 | BV13: 0 | BW13: 0 | BX13: 1 | BY13: 0 | BZ13: 0 | CA13: 0 | CB13: 0 | CC13: 0 | CD13: 1 | CE13: 0 | CF13: 1 | CG13: 0 | CH13: 1 | CI13: 0 | CJ13: 0 | CK13: 0 | CL13: 0 | CM13: 0 | CN13: 0 | CO13: 0 | CP13: 0 | CQ13: 1 | CR13: 1 | CS13: 0 | CT13: 0 | CU13: 1 | CV13: 0 | CW13: 0 | CX13: 0 | CY13: 0 | CZ13: 0 | DA13: 1 | DB13: 0 | DC13: 1 | DD13: 0 | DE13: 0 | DF13: 1 | DG13: 0 | DH13: 1 | DI13: 0 | DJ13: 0 | DK13: 0 | DL13: 0 | DM13: 0 | DN13: 0 | DO13: 1 | DP13: 1 | DQ13: 0 | DR13: 0 | DS13: 0 | DT13: 0 | DU13: 0 | DV13: 0 | DW13: 0 | DX13: 1 | DY13: 0 | DZ13: 0 | EA13: 1 | EB13: 1 | EC13: C | ED13: A | EE13: B | EF13: C | EG13: A | EH13: A | EI13: A | EJ13: C | EK13: B | EL13: D | EM13: B | EN13: C | EO13: D | EP13: C | EQ13: A | ER13: A | ES13: C | ET13: B | EU13: B | EV13: A | EW13: D | EX13: C | EY13: B | EZ13: C | FA13: A | FB13: D | FC13: A | FD13: C | FE13: C | FF13: A | FG13: B | FH13: C | FI13: B | FJ13: A | FK13: A | FL13: D | FM13: B | FN13: D | FO13: A | FP13: C | FQ13: D | FR13: C | FS13: C | FT13: B | FU13: D | FV13: A | FW13: A | FX13: B | FY13: C | FZ13: D | GA13: B | GB13: D | GC13: C | GD13: B | GE13: D | GF13: C | GG13: B | GH13: A | GI13: D | GJ13: C | GK13: B | GL13: C | GM13: A | GN13: C | GO13: B | GP13: D | GQ13: D | GR13: C | GS13: B | GT13: C | GU13: C | GV13: A | GW13: D | GX13: B | GY13: A | GZ13: A | HA13: D | HB13: B | HC13: B | HD13: D | HE13: C | HF13: A | HG13: C | HH13: B | HI13: C | HJ13: D | HK13: B | HL13: A | HM13: C | HN13: B | HO13: D | HP13: C | HQ13: C | HR13: B | HS13: C | HT13: B | HU13: D | HV13: A | HW13: B | HX13: B | HY13: A | HZ13: C | IA13: D | IB13: C | IC13: A | ID13: B | IE13: A | IF13: B | IG13: A | IH13: C | II13: D | IJ13: C | IK13: A | IL13: C | IM13: D | IN13: B | IO13: B | IP13: A | IQ13: D | IR13: C
A14: cerro tofeme monteria 1sesion [4053] | D14: CASTAÑO EMERIS DANIELA LUCIA | E14: 5802 | G14: 33.0 | H14: 120.0 | I14: 27.5 | J14: mar. 14 2026 09:30 a.Â m. | K14: mar. 14 2026 09:34 a.Â m. | M14: 1 | N14: 1 | O14: 0 | P14: 0 | Q14: 0 | R14: 0 | S14: 0 | T14: 1 | U14: 0 | V14: 0 | W14: 1 | X14: 1 | Y14: 1 | Z14: 0 | AA14: 0 | AB14: 0 | AC14: 1 | AD14: 0 | AE14: 1 | AF14: 0 | AG14: 0 | AH14: 0 | AI14: 0 | AJ14: 0 | AK14: 0 | AL14: 0 | AM14: 0 | AN14: 0 | AO14: 0 | AP14: 0 | AQ14: 0 | AR14: 1 | AS14: 0 | AT14: 0 | AU14: 1 | AV14: 0 | AW14: 1 | AX14: 0 | AY14: 0 | AZ14: 0 | BA14: 1 | BB14: 0 | BC14: 0 | BD14: 0 | BE14: 0 | BF14: 0 | BG14: 1 | BH14: 1 | BI14: 0 | BJ14: 0 | BK14: 0 | BL14: 0 | BM14: 1 | BN14: 1 | BO14: 0 | BP14: 0 | BQ14: 0 | BR14: 1 | BS14: 0 | BT14: 0 | BU14: 1 | BV14: 0 | BW14: 0 | BX14: 0 | BY14: 1 | BZ14: 0 | CA14: 0 | CB14: 0 | CC14: 0 | CD14: 0 | CE14: 1 | CF14: 0 | CG14: 0 | CH14: 1 | CI14: 0 | CJ14: 1 | CK14: 0 | CL14: 1 | CM14: 0 | CN14: 0 | CO14: 0 | CP14: 0 | CQ14: 1 | CR14: 1 | CS14: 0 | CT14: 0 | CU14: 1 | CV14: 1 | CW14: 0 | CX14: 0 | CY14: 0 | CZ14: 0 | DA14: 1 | DB14: 0 | DC14: 0 | DD14: 0 | DE14: 0 | DF14: 0 | DG14: 0 | DH14: 0 | DI14: 0 | DJ14: 0 | DK14: 1 | DL14: 0 | DM14: 0 | DN14: 1 | DO14: 0 | DP14: 0 | DQ14: 1 | DR14: 0 | DS14: 0 | DT14: 0 | DU14: 0 | DV14: 1 | DW14: 1 | DX14: 0 | DY14: 0 | DZ14: 0 | EA14: 0 | EB14: 0 | EC14: C | ED14: B | EE14: A | EF14: C | EG14: D | EH14: C | EI14: A | EJ14: C | EK14: C | EL14: B | EM14: C | EN14: C | EO14: D | EP14: B | EQ14: A | ER14: A | ES14: D | ET14: A | EU14: D | EV14: A | EW14: A | EX14: B | EY14: C | EZ14: B | FA14: D | FB14: D | FC14: C | FD14: D | FE14: B | FF14: D | FG14: A | FH14: D | FI14: B | FJ14: A | FK14: A | FL14: C | FM14: A | FN14: C | FO14: B | FP14: D | FQ14: D | FR14: B | FS14: B | FT14: D | FV14: A | FW14: D | FX14: B | FY14: C | FZ14: D | GA14: C | GB14: D | GC14: D | GD14: B | GE14: B | GF14: A | GG14: C | GH14: A | GI14: D | GJ14: B | GK14: D | GL14: A | GM14: A | GN14: D | GO14: D | GP14: D | GQ14: D | GR14: B | GS14: C | GT14: B | GU14: D | GV14: C | GW14: A | GX14: B | GY14: A | GZ14: C | HA14: D | HB14: D | HC14: B | HD14: C | HE14: D | HF14: A | HG14: C | HH14: B | HI14: C | HJ14: D | HK14: B | HL14: B | HM14: C | HN14: B | HO14: C | HP14: C | HQ14: C | HR14: C | HS14: B | HT14: C | HV14: B | HW14: C | HX14: C | HY14: A | HZ14: A | IA14: C | IB14: C | IC14: A | ID14: A | IE14: C | IF14: A | IG14: C | IH14: B | II14: A | IJ14: B | IK14: C | IL14: B | IM14: C | IN14: A | IO14: D | IP14: A | IQ14: A | IR14: B
A15: cerro tofeme monteria 1sesion [4053] | D15: CAUSIL RAMOS SANTIAGO DAVID | E15: 5803 | G15: 29.0 | H15: 120.0 | I15: 24.2 | J15: mar. 14 2026 09:30 a.Â m. | K15: mar. 14 2026 09:34 a.Â m. | M15: 0 | N15: 1 | O15: 0 | P15: 0 | Q15: 0 | R15: 0 | S15: 0 | T15: 1 | U15: 0 | V15: 0 | W15: 0 | X15: 0 | Y15: 0 | Z15: 1 | AA15: 0 | AB15: 0 | AC15: 0 | AD15: 0 | AE15: 0 | AF15: 0 | AG15: 0 | AH15: 1 | AI15: 0 | AJ15: 0 | AK15: 1 | AL15: 1 | AM15: 0 | AN15: 0 | AO15: 1 | AP15: 0 | AQ15: 0 | AR15: 1 | AS15: 0 | AT15: 0 | AU15: 1 | AV15: 1 | AW15: 0 | AX15: 0 | AY15: 0 | AZ15: 0 | BA15: 0 | BB15: 0 | BC15: 0 | BD15: 0 | BE15: 0 | BF15: 0 | BG15: 0 | BH15: 1 | BI15: 0 | BJ15: 0 | BK15: 1 | BL15: 0 | BM15: 1 | BN15: 0 | BO15: 0 | BP15: 0 | BQ15: 0 | BR15: 0 | BS15: 0 | BT15: 0 | BU15: 0 | BV15: 0 | BW15: 0 | BX15: 0 | BY15: 0 | BZ15: 0 | CA15: 0 | CB15: 0 | CC15: 0 | CD15: 0 | CE15: 0 | CF15: 0 | CG15: 0 | CH15: 0 | CI15: 0 | CJ15: 0 | CK15: 1 | CL15: 0 | CM15: 0 | CN15: 1 | CO15: 1 | CP15: 0 | CQ15: 0 | CR15: 0 | CS15: 0 | CT15: 0 | CU15: 1 | CV15: 0 | CW15: 0 | CX15: 0 | CY15: 0 | CZ15: 1 | DA15: 0 | DB15: 0 | DC15: 1 | DD15: 0 | DE15: 0 | DF15: 1 | DG15: 0 | DH15: 1 | DI15: 1 | DJ15: 0 | DK15: 0 | DL15: 0 | DM15: 0 | DN15: 1 | DO15: 1 | DP15: 1 | DQ15: 1 | DR15: 0 | DS15: 1 | DT15: 0 | DU15: 1 | DV15: 0 | DW15: 0 | DX15: 0 | DY15: 0 | DZ15: 1 | EA15: 0 | EB15: 0 | EC15: D | ED15: B | EE15: A | EF15: C | EG15: D | EH15: A | EI15: A | EJ15: C | EK15: D | EL15: A | EM15: A | EN15: D | EO15: B | EP15: A | EQ15: D | ER15: D | ES15: B | ET15: B | EU15: C | EV15: A | EW15: C | EX15: C | EY15: A | EZ15: D | FA15: C | FB15: A | FC15: A | FD15: A | FE15: C | FF15: B | FG15: D | FH15: D | FI15: A | FJ15: C | FK15: A | FL15: D | FM15: C | FN15: A | FO15: B | FP15: A | FQ15: A | FR15: B | FS15: A | FT15: C | FU15: A | FV15: A | FW15: B | FX15: B | FY15: B | FZ15: D | GA15: B | GB15: B | GC15: D | GD15: C | GE15: A | GF15: A | GG15: C | GH15: B | GI15: C | GJ15: A | GK15: B | GL15: A | GM15: D | GN15: B | GO15: A | GP15: B | GQ15: C | GR15: C | GS15: C | GT15: A | GU15: C | GV15: B | GW15: D | GX15: A | GY15: C | GZ15: A | HA15: A | HB15: B | HC15: A | HD15: A | HE15: A | HF15: A | HG15: D | HH15: A | HI15: C | HJ15: A | HK15: B | HL15: A | HM15: B | HN15: B | HO15: A | HP15: B | HQ15: B | HR15: C | HS15: C | HT15: B | HU15: A | HV15: A | HW15: B | HX15: B | HY15: C | HZ15: D | IA15: A | IB15: C | IC15: A | ID15: A | IE15: A | IF15: B | IG15: C | IH15: D | II15: C | IJ15: C | IK15: B | IL15: C | IM15: A | IN15: A | IO15: A | IP15: C | IQ15: C | IR15: B
A16: cerro tofeme monteria 1sesion [4053] | D16: CHAMORRO ARTEAGA JUAN DAVID | E16: 5804 | G16: 39.0 | H16: 120.0 | I16: 32.5 | J16: mar. 14 2026 09:30 a.Â m. | K16: mar. 14 2026 09:34 a.Â m. | M16: 1 | N16: 1 | O16: 0 | P16: 0 | Q16: 0 | R16: 1 | S16: 1 | T16: 0 | U16: 1 | V16: 0 | W16: 0 | X16: 0 | Y16: 1 | Z16: 0 | AA16: 1 | AB16: 0 | AC16: 0 | AD16: 0 | AE16: 1 | AF16: 0 | AG16: 0 | AH16: 0 | AI16: 1 | AJ16: 0 | AK16: 1 | AL16: 1 | AM16: 0 | AN16: 1 | AO16: 1 | AP16: 1 | AQ16: 0 | AR16: 0 | AS16: 1 | AT16: 1 | AU16: 0 | AV16: 0 | AW16: 1 | AX16: 0 | AY16: 0 | AZ16: 0 | BA16: 0 | BB16: 0 | BC16: 0 | BD16: 0 | BE16: 0 | BF16: 0 | BG16: 0 | BH16: 1 | BI16: 1 | BJ16: 0 | BK16: 0 | BL16: 1 | BM16: 0 | BN16: 1 | BO16: 0 | BP16: 0 | BQ16: 0 | BR16: 0 | BS16: 0 | BT16: 0 | BU16: 0 | BV16: 0 | BW16: 0 | BX16: 0 | BY16: 0 | BZ16: 1 | CA16: 0 | CB16: 1 | CC16: 1 | CD16: 1 | CE16: 0 | CF16: 0 | CG16: 0 | CH16: 0 | CI16: 0 | CJ16: 1 | CK16: 1 | CL16: 0 | CM16: 0 | CN16: 1 | CO16: 0 | CP16: 0 | CQ16: 1 | CR16: 0 | CS16: 1 | CT16: 1 | CU16: 0 | CV16: 0 | CW16: 0 | CX16: 0 | CY16: 0 | CZ16: 1 | DA16: 0 | DB16: 0 | DC16: 0 | DD16: 0 | DE16: 0 | DF16: 0 | DG16: 0 | DH16: 0 | DI16: 0 | DJ16: 0 | DK16: 0 | DL16: 1 | DM16: 0 | DN16: 0 | DO16: 0 | DP16: 0 | DQ16: 0 | DR16: 1 | DS16: 1 | DT16: 0 | DU16: 0 | DV16: 0 | DW16: 0 | DX16: 1 | DY16: 1 | DZ16: 1 | EA16: 0 | EB16: 1 | EC16: C | ED16: B | EE16: C | EF16: A | EG16: D | EH16: B | EI16: D | EJ16: D | EK16: B | EL16: B | EM16: B | EN16: D | EO16: D | EP16: C | EQ16: B | ER16: B | ES16: A | ET16: B | EU16: D | EV16: C | EW16: A | EX16: B | EY16: D | EZ16: B | FA16: C | FB16: A | FC16: A | FD16: C | FE16: C | FF16: C | FG16: D | FH16: A | FI16: C | FJ16: D | FK16: D | FL16: A | FM16: A | FN16: C | FO16: B | FP16: D | FQ16: B | FR16: C | FS16: A | FT16: C | FU16: B | FV16: A | FW16: A | FX16: B | FY16: D | FZ16: A | GA16: C | GB16: C | GC16: C | GD16: B | GE16: B | GF16: A | GG16: D | GH16: D | GI16: C | GJ16: A | GK16: B | GL16: C | GM16: A | GN16: D | GO16: B | GP16: C | GQ16: C | GR16: A | GS16: A | GT16: C | GU16: A | GV16: B | GW16: D | GX16: A | GY16: C | GZ16: C | HA16: A | HB16: A | HC16: B | HD16: A | HE16: B | HF16: B | HG16: C | HH16: A | HI16: B | HJ16: C | HK16: D | HL16: A | HM16: B | HN16: C | HO16: C | HP16: B | HQ16: D | HR16: C | HS16: A | HT16: A | HU16: C | HV16: B | HW16: D | HX16: A | HY16: B | HZ16: D | IA16: A | IB16: B | IC16: C | ID16: C | IE16: B | IF16: D | IG16: B | IH16: A | II16: C | IJ16: B | IK16: C | IL16: C | IM16: D | IN16: B | IO16: C | IP16: C | IQ16: C | IR16: C
A17: cerro tofeme monteria 1sesion [4053] | D17: FLOREZ HERNANDEZ BRAYAN ANDRES | E17: 5850 | G17: 55.0 | H17: 120.0 | I17: 45.8 | J17: mar. 14 2026 09:30 a.Â m. | K17: mar. 14 2026 09:34 a.Â m. | M17: 1 | N17: 0 | O17: 0 | P17: 0 | Q17: 1 | R17: 0 | S17: 0 | T17: 0 | U17: 0 | V17: 0 | W17: 0 | X17: 1 | Y17: 0 | Z17: 0 | AA17: 0 | AB17: 0 | AC17: 0 | AD17: 0 | AE17: 1 | AF17: 0 | AG17: 1 | AH17: 1 | AI17: 0 | AJ17: 0 | AK17: 0 | AL17: 1 | AM17: 0 | AN17: 0 | AO17: 1 | AP17: 0 | AQ17: 1 | AR17: 1 | AS17: 0 | AT17: 0 | AU17: 1 | AV17: 1 | AW17: 1 | AX17: 0 | AY17: 1 | AZ17: 0 | BA17: 0 | BB17: 1 | BC17: 1 | BD17: 0 | BE17: 0 | BF17: 0 | BG17: 0 | BH17: 1 | BI17: 1 | BJ17: 0 | BK17: 0 | BL17: 1 | BM17: 1 | BN17: 0 | BO17: 1 | BP17: 1 | BQ17: 1 | BR17: 1 | BS17: 0 | BT17: 0 | BU17: 0 | BV17: 1 | BW17: 1 | BX17: 1 | BY17: 0 | BZ17: 1 | CA17: 0 | CB17: 1 | CC17: 1 | CD17: 0 | CE17: 1 | CF17: 0 | CG17: 0 | CH17: 1 | CI17: 1 | CJ17: 0 | CK17: 1 | CL17: 1 | CM17: 0 | CN17: 1 | CO17: 1 | CP17: 0 | CQ17: 1 | CR17: 0 | CS17: 1 | CT17: 1 | CU17: 0 | CV17: 0 | CW17: 0 | CX17: 0 | CY17: 0 | CZ17: 1 | DA17: 0 | DB17: 0 | DC17: 0 | DD17: 1 | DE17: 0 | DF17: 1 | DG17: 1 | DH17: 1 | DI17: 1 | DJ17: 0 | DK17: 1 | DL17: 0 | DM17: 0 | DN17: 1 | DO17: 0 | DP17: 1 | DQ17: 0 | DR17: 1 | DS17: 0 | DT17: 0 | DU17: 0 | DV17: 1 | DW17: 0 | DX17: 1 | DY17: 0 | DZ17: 1 | EA17: 1 | EB17: 1 | EC17: C | ED17: A | EE17: D | EF17: D | EG17: C | EH17: A | EI17: A | EJ17: B | EK17: C | EL17: A | EM17: B | EN17: C | EO17: C | EP17: D | EQ17: A | ER17: A | ES17: A | ET17: D | EU17: D | EV17: A | EW17: B | EX17: C | EY17: B | EZ17: D | FA17: A | FB17: A | FC17: A | FD17: A | FE17: C | FF17: A | FG17: C | FH17: D | FI17: B | FJ17: C | FK17: A | FL17: D | FM17: A | FN17: B | FO17: C | FP17: D | FQ17: A | FR17: D | FS17: D | FT17: C | FU17: A | FV17: A | FW17: B | FX17: B | FY17: D | FZ17: D | GA17: A | GB17: C | GC17: D | GD17: C | GE17: C | GF17: B | GG17: B | GH17: A | GI17: D | GJ17: A | GK17: B | GL17: D | GM17: B | GN17: C | GO17: A | GP17: C | GQ17: D | GR17: A | GS17: A | GT17: D | GU17: D | GV17: C | GW17: D | GX17: B | GY17: B | GZ17: D | HA17: A | HB17: D | HC17: A | HD17: A | HE17: A | HF17: D | HG17: C | HH17: D | HI17: B | HJ17: C | HK17: D | HL17: C | HM17: B | HN17: D | HO17: D | HP17: B | HQ17: B | HR17: C | HS17: B | HT17: D | HU17: C | HV17: A | HW17: A | HX17: B | HY17: C | HZ17: D | IA17: C | IB17: C | IC17: D | ID17: A | IE17: B | IF17: B | IG17: B | IH17: A | II17: A | IJ17: B | IK17: D | IL17: B | IM17: D | IN17: B | IO17: B | IP17: C | IQ17: D | IR17: C
A18: cerro tofeme monteria 1sesion [4053] | D18: LOZANO BENITEZ HECTOR DAVID | E18: 5806 | G18: 42.0 | H18: 120.0 | I18: 35.0 | J18: mar. 14 2026 09:30 a.Â m. | K18: mar. 14 2026 09:34 a.Â m. | M18: 1 | N18: 0 | O18: 0 | P18: 0 | Q18: 0 | R18: 0 | S18: 0 | T18: 1 | U18: 1 | V18: 1 | W18: 1 | X18: 0 | Y18: 0 | Z18: 0 | AA18: 0 | AB18: 1 | AC18: 1 | AD18: 0 | AE18: 0 | AF18: 1 | AG18: 0 | AH18: 1 | AI18: 0 | AJ18: 1 | AK18: 1 | AL18: 0 | AM18: 0 | AN18: 1 | AO18: 1 | AP18: 0 | AQ18: 1 | AR18: 1 | AS18: 1 | AT18: 0 | AU18: 1 | AV18: 1 | AW18: 0 | AX18: 0 | AY18: 0 | AZ18: 1 | BA18: 1 | BB18: 0 | BC18: 0 | BD18: 1 | BE18: 1 | BF18: 0 | BG18: 0 | BH18: 1 | BI18: 1 | BJ18: 0 | BK18: 1 | BL18: 0 | BM18: 0 | BN18: 1 | BO18: 0 | BP18: 0 | BQ18: 0 | BR18: 1 | BS18: 0 | BT18: 0 | BU18: 0 | BV18: 0 | BW18: 0 | BX18: 0 | BY18: 0 | BZ18: 0 | CA18: 0 | CB18: 1 | CC18: 0 | CD18: 0 | CE18: 1 | CF18: 1 | CG18: 0 | CH18: 0 | CI18: 0 | CJ18: 0 | CK18: 0 | CL18: 0 | CM18: 0 | CN18: 0 | CO18: 0 | CP18: 0 | CQ18: 0 | CR18: 0 | CS18: 0 | CT18: 1 | CU18: 0 | CV18: 0 | CW18: 0 | CX18: 0 | CY18: 1 | CZ18: 1 | DA18: 0 | DB18: 1 | DC18: 0 | DD18: 0 | DE18: 0 | DF18: 1 | DG18: 0 | DH18: 1 | DI18: 0 | DJ18: 0 | DK18: 0 | DL18: 0 | DM18: 1 | DN18: 0 | DO18: 1 | DP18: 1 | DQ18: 0 | DR18: 0 | DS18: 0 | DT18: 0 | DU18: 0 | DV18: 1 | DW18: 0 | DX18: 0 | DY18: 0 | DZ18: 0 | EA18: 1 | EB18: 1 | EC18: C | ED18: C | EE18: A | EF18: C | EG18: D | EH18: A | EI18: A | EJ18: C | EK18: B | EL18: C | EM18: C | EN18: D | EO18: C | EP18: C | EQ18: D | ER18: C | ES18: D | ET18: A | EU18: B | EV18: D | EW18: D | EX18: C | EY18: A | EZ18: C | FA18: C | FB18: B | FC18: D | FD18: C | FE18: C | FF18: B | FG18: C | FH18: D | FI18: C | FJ18: C | FK18: A | FL18: D | FM18: D | FN18: A | FO18: A | FP18: C | FQ18: D | FR18: A | FS18: C | FT18: B | FU18: D | FV18: D | FW18: C | FX18: B | FY18: D | FZ18: B | GA18: B | GB18: D | GC18: A | GD18: B | GE18: B | GF18: C | GG18: A | GH18: A | GI18: B | GJ18: A | GK18: A | GL18: C | GM18: A | GN18: A | GO18: C | GP18: B | GQ18: C | GR18: A | GS18: D | GT18: A | GU18: D | GV18: A | GW18: A | GX18: D | GY18: C | GZ18: A | HA18: C | HB18: B | HC18: A | HD18: C | HE18: D | HF18: B | HG18: A | HH18: A | HI18: A | HJ18: C | HK18: C | HL18: A | HM18: A | HN18: C | HO18: B | HP18: B | HQ18: A | HR18: A | HS18: B | HT18: A | HU18: D | HV18: A | HW18: D | HX18: B | HY18: A | HZ18: A | IA18: D | IB18: A | IC18: B | ID18: C | IE18: A | IF18: B | IG18: A | IH18: C | II18: D | IJ18: B | IK18: A | IL18: B | IM18: B | IN18: D | IP18: B | IQ18: D | IR18: C
A19: cerro tofeme monteria 1sesion [4053] | D19: MACHADO CARVAJAL YANDRI VANESSA | E19: 5807 | G19: 42.0 | H19: 120.0 | I19: 35.0 | J19: mar. 14 2026 09:30 a.Â m. | K19: mar. 14 2026 09:34 a.Â m. | M19: 1 | N19: 1 | O19: 0 | P19: 0 | Q19: 0 | R19: 1 | S19: 0 | T19: 1 | U19: 1 | V19: 1 | W19: 0 | X19: 0 | Y19: 0 | Z19: 0 | AA19: 1 | AB19: 0 | AC19: 0 | AD19: 0 | AE19: 1 | AF19: 0 | AG19: 1 | AH19: 0 | AI19: 1 | AJ19: 1 | AK19: 0 | AL19: 1 | AM19: 1 | AN19: 0 | AO19: 0 | AP19: 0 | AQ19: 1 | AR19: 0 | AS19: 1 | AT19: 0 | AU19: 0 | AV19: 0 | AW19: 0 | AX19: 0 | AY19: 0 | AZ19: 0 | BA19: 0 | BB19: 0 | BC19: 0 | BD19: 1 | BE19: 0 | BF19: 0 | BG19: 0 | BH19: 1 | BI19: 1 | BJ19: 1 | BK19: 0 | BL19: 1 | BM19: 1 | BN19: 1 | BO19: 0 | BP19: 0 | BQ19: 1 | BR19: 0 | BS19: 1 | BT19: 0 | BU19: 0 | BV19: 0 | BW19: 1 | BX19: 0 | BY19: 1 | BZ19: 1 | CA19: 1 | CB19: 0 | CC19: 0 | CD19: 1 | CE19: 0 | CF19: 1 | CG19: 0 | CH19: 0 | CI19: 1 | CJ19: 0 | CK19: 1 | CL19: 0 | CM19: 0 | CN19: 0 | CO19: 0 | CP19: 0 | CQ19: 1 | CR19: 1 | CS19: 0 | CT19: 0 | CU19: 0 | CV19: 0 | CW19: 0 | CX19: 0 | CY19: 0 | CZ19: 1 | DA19: 0 | DB19: 1 | DC19: 0 | DD19: 0 | DE19: 0 | DF19: 0 | DG19: 0 | DH19: 0 | DI19: 0 | DJ19: 0 | DK19: 0 | DL19: 1 | DM19: 0 | DN19: 0 | DO19: 0 | DP19: 1 | DQ19: 0 | DR19: 0 | DS19: 0 | DT19: 0 | DU19: 1 | DV19: 0 | DW19: 1 | DX19: 0 | DY19: 0 | DZ19: 1 | EA19: 0 | EB19: 1 | EC19: C | ED19: B | EE19: A | EF19: C | EG19: D | EH19: B | EI19: B | EJ19: C | EK19: B | EL19: C | EM19: B | EN19: D | EO19: C | EP19: C | EQ19: B | ER19: A | ES19: A | ET19: D | EU19: D | EV19: C | EW19: B | EX19: A | EY19: D | EZ19: C | FA19: B | FB19: A | FC19: B | FD19: D | FE19: D | FF19: D | FG19: C | FH19: C | FI19: C | FJ19: C | FK19: D | FL19: A | FM19: B | FN19: C | FO19: D | FP19: D | FQ19: B | FR19: C | FS19: A | FT19: B | FU19: C | FV19: A | FW19: B | FX19: B | FY19: D | FZ19: C | GA19: A | GB19: C | GC19: D | GD19: B | GE19: B | GF19: C | GG19: B | GH19: C | GI19: A | GJ19: A | GK19: B | GL19: C | GM19: B | GN19: B | GO19: D | GP19: C | GQ19: B | GR19: D | GS19: B | GT19: C | GU19: C | GV19: A | GW19: D | GX19: A | GY19: B | GZ19: D | HA19: A | HB19: B | HC19: A | HD19: C | HE19: B | HF19: A | HG19: C | HH19: B | HI19: D | HJ19: D | HK19: C | HL19: D | HM19: B | HN19: C | HO19: A | HP19: B | HQ19: B | HR19: A | HS19: B | HT19: C | HU19: C | HV19: B | HW19: D | HX19: C | HY19: B | HZ19: A | IA19: B | IB19: B | IC19: A | ID19: D | IE19: B | IF19: B | IG19: A | IH19: C | II19: A | IJ19: D | IK19: B | IL19: C | IM19: C | IN19: A | IO19: B | IP19: C | IQ19: C | IR19: C
A20: cerro tofeme monteria 1sesion [4053] | D20: MARTINEZ CAUCIL SARETH MILENA | E20: 5808 | G20: 37.0 | H20: 120.0 | I20: 30.8 | J20: mar. 14 2026 09:30 a.Â m. | K20: mar. 14 2026 09:34 a.Â m. | M20: 0 | N20: 1 | O20: 0 | P20: 0 | Q20: 0 | R20: 0 | S20: 0 | T20: 1 | U20: 0 | V20: 1 | W20: 1 | X20: 0 | Y20: 1 | Z20: 1 | AA20: 0 | AB20: 0 | AC20: 0 | AD20: 0 | AE20: 0 | AF20: 1 | AG20: 1 | AH20: 0 | AI20: 0 | AJ20: 0 | AK20: 0 | AL20: 0 | AM20: 1 | AN20: 0 | AO20: 0 | AP20: 1 | AQ20: 0 | AR20: 0 | AS20: 0 | AT20: 1 | AU20: 1 | AV20: 1 | AW20: 0 | AX20: 0 | AY20: 1 | AZ20: 0 | BA20: 0 | BB20: 0 | BC20: 0 | BD20: 0 | BE20: 0 | BF20: 0 | BG20: 0 | BH20: 1 | BI20: 1 | BJ20: 1 | BK20: 0 | BL20: 0 | BM20: 0 | BN20: 0 | BO20: 0 | BP20: 0 | BQ20: 0 | BR20: 0 | BS20: 0 | BT20: 0 | BU20: 0 | BV20: 0 | BW20: 0 | BX20: 1 | BY20: 0 | BZ20: 0 | CA20: 0 | CB20: 0 | CC20: 1 | CD20: 0 | CE20: 0 | CF20: 0 | CG20: 1 | CH20: 1 | CI20: 0 | CJ20: 0 | CK20: 0 | CL20: 0 | CM20: 0 | CN20: 0 | CO20: 0 | CP20: 0 | CQ20: 0 | CR20: 1 | CS20: 0 | CT20: 0 | CU20: 0 | CV20: 1 | CW20: 0 | CX20: 0 | CY20: 0 | CZ20: 0 | DA20: 0 | DB20: 1 | DC20: 1 | DD20: 0 | DE20: 0 | DF20: 0 | DG20: 1 | DH20: 1 | DI20: 0 | DJ20: 1 | DK20: 1 | DL20: 0 | DM20: 1 | DN20: 0 | DO20: 1 | DP20: 1 | DQ20: 1 | DR20: 1 | DS20: 0 | DT20: 0 | DU20: 1 | DV20: 1 | DW20: 0 | DX20: 0 | DY20: 0 | DZ20: 1 | EA20: 0 | EB20: 0 | EC20: A | ED20: B | EE20: C | EF20: A | EG20: D | EH20: C | EI20: A | EJ20: C | EK20: C | EL20: C | EM20: C | EN20: D | EO20: D | EP20: A | EQ20: C | ER20: A | ES20: A | ET20: A | EU20: A | EV20: D | EW20: B | EX20: B | EY20: C | EZ20: A | FA20: A | FB20: D | FC20: B | FD20: B | FE20: A | FF20: C | FG20: D | FH20: A | FI20: A | FJ20: D | FK20: A | FL20: D | FM20: B | FN20: B | FO20: C | FP20: A | FQ20: C | FR20: C | FS20: B | FT20: C | FU20: A | FV20: A | FW20: C | FX20: B | FY20: D | FZ20: C | GA20: C | GB20: B | GC20: C | GD20: D | GE20: A | GF20: A | GG20: D | GH20: D | GI20: B | GJ20: A | GK20: B | GL20: C | GM20: A | GN20: C | GO20: B | GP20: D | GQ20: D | GR20: B | GS20: A | GT20: B | GU20: C | GV20: B | GW20: C | GX20: B | GY20: A | GZ20: D | HA20: D | HB20: B | HC20: C | HD20: B | HE20: C | HF20: D | HG20: A | HH20: B | HI20: C | HJ20: D | HK20: D | HL20: B | HM20: B | HN20: D | HO20: C | HP20: C | HQ20: D | HR20: A | HS20: C | HT20: C | HU20: C | HV20: B | HW20: A | HX20: B | HY20: D | HZ20: B | IA20: C | IB20: D | IC20: B | ID20: C | IE20: A | IF20: B | IG20: C | IH20: A | II20: B | IJ20: C | IK20: B | IL20: B | IM20: A | IN20: A | IO20: D | IP20: C | IQ20: B | IR20: B
A21: cerro tofeme monteria 1sesion [4053] | D21: MERCADO RAMOS DANIELA SOFIA | E21: 5810 | G21: 25.0 | H21: 120.0 | I21: 20.8 | J21: mar. 14 2026 09:31 a.Â m. | K21: mar. 14 2026 09:34 a.Â m. | M21: 0 | N21: 1 | O21: 0 | P21: 0 | Q21: 0 | R21: 1 | S21: 0 | T21: 0 | U21: 0 | V21: 0 | W21: 0 | X21: 1 | Y21: 1 | Z21: 0 | AA21: 1 | AB21: 0 | AC21: 0 | AD21: 0 | AE21: 0 | AF21: 0 | AG21: 0 | AH21: 0 | AI21: 0 | AJ21: 0 | AK21: 1 | AL21: 1 | AM21: 0 | AN21: 0 | AO21: 1 | AP21: 0 | AQ21: 0 | AR21: 0 | AS21: 0 | AT21: 0 | AU21: 0 | AV21: 0 | AW21: 0 | AX21: 0 | AY21: 0 | AZ21: 1 | BA21: 0 | BB21: 0 | BC21: 0 | BD21: 0 | BE21: 0 | BF21: 0 | BG21: 0 | BH21: 1 | BI21: 0 | BJ21: 0 | BK21: 0 | BL21: 1 | BM21: 0 | BN21: 0 | BO21: 0 | BP21: 1 | BQ21: 0 | BR21: 0 | BS21: 0 | BT21: 0 | BU21: 0 | BV21: 0 | BW21: 0 | BX21: 0 | BY21: 0 | BZ21: 1 | CA21: 1 | CB21: 0 | CC21: 0 | CD21: 1 | CE21: 0 | CF21: 0 | CG21: 1 | CH21: 1 | CI21: 0 | CJ21: 0 | CK21: 0 | CL21: 0 | CM21: 0 | CN21: 0 | CO21: 0 | CP21: 1 | CQ21: 0 | CR21: 0 | CS21: 1 | CT21: 0 | CU21: 1 | CV21: 0 | CW21: 0 | CX21: 0 | CY21: 0 | CZ21: 0 | DA21: 0 | DB21: 0 | DC21: 0 | DD21: 0 | DE21: 0 | DF21: 0 | DG21: 0 | DH21: 0 | DI21: 0 | DJ21: 1 | DK21: 1 | DL21: 0 | DM21: 0 | DN21: 0 | DO21: 0 | DP21: 1 | DQ21: 1 | DR21: 1 | DS21: 0 | DT21: 0 | DU21: 0 | DV21: 0 | DW21: 0 | DX21: 0 | DY21: 0 | DZ21: 0 | EA21: 0 | EB21: 0 | EC21: D | ED21: B | EE21: A | EF21: C | EG21: D | EH21: B | EI21: C | EJ21: A | EK21: D | EL21: B | EM21: D | EN21: C | EO21: D | EP21: C | EQ21: B | ER21: D | ES21: B | ET21: B | EU21: C | EV21: A | EW21: D | EX21: D | EY21: B | EZ21: B | FA21: C | FB21: A | FC21: A | FD21: B | FE21: C | FF21: A | FG21: D | FH21: C | FI21: D | FJ21: C | FK21: B | FL21: C | FM21: B | FN21: A | FO21: B | FP21: C | FQ21: B | FR21: A | FS21: B | FT21: C | FU21: A | FV21: B | FW21: C | FX21: B | FY21: C | FZ21: B | GA21: A | GB21: C | GC21: A | GD21: D | GE21: A | GF21: B | GG21: C | GH21: D | GI21: B | GJ21: A | GK21: C | GL21: B | GM21: C | GN21: D | GO21: A | GP21: C | GQ21: B | GR21: B | GS21: B | GT21: C | GU21: A | GV21: D | GW21: C | GX21: B | GY21: C | GZ21: B | HA21: D | HB21: A | HC21: C | HD21: B | HE21: D | HF21: C | HG21: A | HH21: C | HI21: B | HJ21: D | HK21: B | HL21: C | HM21: C | HN21: B | HO21: D | HP21: C | HQ21: A | HR21: C | HS21: D | HT21: B | HU21: C | HV21: B | HW21: D | HX21: D | HY21: D | HZ21: B | IA21: C | IB21: C | IC21: D | ID21: B | IE21: C | IF21: B | IG21: C | IH21: A | II21: B | IJ21: C | IK21: A | IL21: C | IM21: B | IN21: A | IO21: B | IP21: B | IQ21: A | IR21: D
A22: cerro tofeme monteria 1sesion [4053] | D22: RAMOS MESTRA FABIAN DE JESUS | E22: 5811 | G22: 33.0 | H22: 120.0 | I22: 27.5 | J22: mar. 14 2026 09:31 a.Â m. | K22: mar. 14 2026 09:34 a.Â m. | M22: 1 | N22: 1 | O22: 0 | P22: 1 | Q22: 1 | R22: 1 | S22: 0 | T22: 0 | U22: 1 | V22: 0 | W22: 1 | X22: 1 | Y22: 0 | Z22: 0 | AA22: 1 | AB22: 0 | AC22: 1 | AD22: 0 | AE22: 1 | AF22: 0 | AG22: 1 | AH22: 0 | AI22: 0 | AJ22: 0 | AK22: 0 | AL22: 1 | AM22: 0 | AN22: 0 | AO22: 1 | AP22: 0 | AQ22: 0 | AR22: 0 | AS22: 0 | AT22: 1 | AU22: 0 | AV22: 0 | AW22: 0 | AX22: 0 | AY22: 1 | AZ22: 0 | BA22: 1 | BB22: 0 | BC22: 0 | BD22: 1 | BE22: 0 | BF22: 0 | BG22: 0 | BH22: 1 | BI22: 0 | BJ22: 0 | BK22: 1 | BL22: 0 | BM22: 0 | BN22: 0 | BO22: 0 | BP22: 1 | BQ22: 0 | BR22: 0 | BS22: 0 | BT22: 0 | BU22: 0 | BV22: 0 | BW22: 0 | BX22: 0 | BY22: 0 | BZ22: 0 | CA22: 0 | CB22: 0 | CC22: 1 | CD22: 0 | CE22: 0 | CF22: 0 | CG22: 0 | CH22: 0 | CI22: 0 | CJ22: 0 | CK22: 0 | CL22: 1 | CM22: 1 | CN22: 1 | CO22: 0 | CP22: 0 | CQ22: 0 | CR22: 0 | CS22: 0 | CT22: 0 | CU22: 1 | CV22: 0 | CW22: 1 | CX22: 0 | CY22: 0 | CZ22: 0 | DA22: 0 | DB22: 0 | DC22: 0 | DD22: 0 | DE22: 0 | DF22: 1 | DG22: 0 | DH22: 0 | DI22: 1 | DJ22: 0 | DK22: 0 | DL22: 0 | DM22: 1 | DN22: 0 | DO22: 0 | DP22: 1 | DQ22: 1 | DR22: 0 | DS22: 0 | DT22: 0 | DU22: 0 | DV22: 1 | DW22: 0 | DX22: 0 | DY22: 0 | DZ22: 0 | EA22: 0 | EB22: 0 | EC22: C | ED22: B | EE22: D | EF22: B | EG22: C | EH22: B | EI22: C | EJ22: D | EK22: B | EL22: B | EM22: C | EN22: C | EO22: A | EP22: C | EQ22: B | ER22: B | ES22: D | ET22: D | EU22: D | EV22: A | EW22: B | EX22: B | EY22: C | EZ22: B | FA22: B | FB22: A | FC22: D | FD22: B | FE22: C | FF22: B | FG22: A | FH22: C | FI22: D | FJ22: D | FK22: C | FL22: B | FM22: B | FN22: A | FO22: C | FP22: D | FQ22: D | FR22: C | FS22: A | FT22: B | FU22: C | FV22: D | FW22: A | FX22: B | FY22: C | FZ22: B | GA22: B | GB22: D | GC22: C | GD22: C | GE22: B | GF22: B | GG22: D | GH22: C | GI22: B | GJ22: A | GK22: B | GL22: B | GM22: C | GN22: D | GO22: B | GP22: D | GQ22: C | GR22: C | GS22: A | GT22: A | GU22: A | GV22: C | GW22: D | GX22: C | GY22: A | GZ22: A | HA22: B | HB22: D | HC22: D | HD22: A | HE22: C | HF22: B | HG22: B | HH22: C | HI22: D | HJ22: A | HK22: B | HL22: C | HM22: D | HN22: D | HO22: A | HP22: C | HQ22: D | HR22: D | HS22: B | HT22: A | HU22: D | HV22: A | HW22: B | HX22: A | HY22: C | HZ22: D | IA22: A | IB22: A | IC22: B | ID22: B | IE22: C | IF22: B | IG22: C | IH22: C | II22: B | IJ22: B | IK22: D | IL22: B | IM22: A | IN22: A | IO22: D | IP22: A | IQ22: C | IR22: A
A23: cerro tofeme monteria 1sesion [4053] | D23: RAMOS RAMOS SEBASTIAN ANDRES | E23: 5812 | G23: 29.0 | H23: 120.0 | I23: 24.2 | J23: mar. 14 2026 09:31 a.Â m. | K23: mar. 14 2026 09:34 a.Â m. | M23: 0 | N23: 0 | O23: 0 | P23: 0 | Q23: 0 | R23: 0 | S23: 0 | T23: 1 | U23: 1 | V23: 0 | W23: 0 | X23: 1 | Y23: 0 | Z23: 0 | AA23: 0 | AB23: 0 | AC23: 0 | AD23: 1 | AE23: 0 | AF23: 1 | AG23: 1 | AH23: 0 | AI23: 0 | AJ23: 0 | AK23: 0 | AL23: 0 | AM23: 0 | AN23: 0 | AO23: 0 | AP23: 0 | AQ23: 0 | AR23: 0 | AS23: 0 | AT23: 0 | AU23: 1 | AV23: 0 | AW23: 1 | AX23: 0 | AY23: 0 | AZ23: 0 | BA23: 0 | BB23: 0 | BC23: 0 | BD23: 0 | BE23: 0 | BF23: 0 | BG23: 0 | BH23: 1 | BI23: 0 | BJ23: 0 | BK23: 0 | BL23: 0 | BM23: 1 | BN23: 0 | BO23: 0 | BP23: 0 | BQ23: 0 | BR23: 0 | BS23: 1 | BT23: 0 | BU23: 0 | BV23: 0 | BW23: 0 | BX23: 0 | BY23: 0 | BZ23: 1 | CA23: 0 | CB23: 1 | CC23: 0 | CD23: 1 | CE23: 1 | CF23: 1 | CG23: 0 | CH23: 1 | CI23: 0 | CJ23: 0 | CK23: 0 | CL23: 0 | CM23: 0 | CN23: 0 | CO23: 0 | CP23: 0 | CQ23: 1 | CR23: 0 | CS23: 0 | CT23: 0 | CU23: 0 | CV23: 0 | CW23: 0 | CX23: 0 | CY23: 1 | CZ23: 0 | DA23: 0 | DB23: 1 | DC23: 0 | DD23: 0 | DE23: 0 | DF23: 1 | DG23: 1 | DH23: 0 | DI23: 0 | DJ23: 0 | DK23: 1 | DL23: 0 | DM23: 0 | DN23: 1 | DO23: 0 | DP23: 1 | DQ23: 1 | DR23: 0 | DS23: 0 | DT23: 1 | DU23: 0 | DV23: 1 | DW23: 0 | DX23: 0 | DY23: 0 | DZ23: 0 | EA23: 0 | EB23: 1 | EC23: A | ED23: C | EE23: D | EF23: C | EG23: D | EH23: A | EI23: C | EJ23: C | EK23: B | EL23: A | EM23: A | EN23: C | EO23: A | EP23: D | EQ23: A | ER23: D | ES23: A | ET23: C | EU23: C | EV23: D | EW23: B | EX23: B | EY23: A | EZ23: D | FA23: D | FB23: B | FC23: C | FD23: A | FE23: D | FF23: A | FG23: B | FH23: A | FI23: A | FJ23: C | FK23: A | FL23: C | FM23: A | FN23: C | FO23: B | FP23: D | FQ23: B | FR23: B | FS23: C | FT23: D | FU23: C | FV23: A | FW23: C | FX23: B | FY23: A | FZ23: B | GA23: A | GB23: B | GC23: D | GD23: A | GE23: D | GF23: C | GG23: C | GH23: D | GI23: A | GJ23: A | GK23: B | GL23: C | GM23: A | GN23: B | GO23: B | GP23: C | GQ23: D | GR23: A | GS23: B | GT23: C | GU23: D | GV23: A | GW23: B | GX23: B | GY23: D | GZ23: B | HA23: C | HB23: C | HC23: A | HD23: B | HE23: B | HF23: B | HG23: C | HH23: D | HI23: C | HJ23: A | HK23: A | HL23: D | HM23: C | HN23: B | HO23: B | HP23: C | HQ23: B | HR23: A | HS23: B | HT23: C | HU23: C | HV23: A | HW23: A | HX23: D | HY23: D | HZ23: A | IA23: C | IB23: C | IC23: A | ID23: A | IE23: C | IF23: B | IG23: C | IH23: B | II23: A | IJ23: A | IK23: C | IL23: B | IM23: D | IN23: C | IO23: D | IP23: A | IQ23: B | IR23: C
